<?xml version="1.0"?>
<!-- dual_arm: two 6-DOF arms (left_arm_ / right_arm_) on a shared base, mounted
     left at y=+0.25 and right at y=-0.25. For multi-tip / dual-arm IK and the
     relative-pose (R9) constraint. Tips: left_arm_tool0, right_arm_tool0.
     12 movable DOF. Primitive-free, license-clean. -->
<robot name="dual_arm">
  <link name="base_link"/>

  <!-- ===================== LEFT ARM ===================== -->
  <joint name="left_arm_mount" type="fixed">
    <parent link="base_link"/>
    <child link="left_arm_base_link"/>
    <origin xyz="0 0.25 0" rpy="0 0 0"/>
  </joint>
  <link name="left_arm_base_link"/>

  <joint name="left_arm_joint1" type="revolute">
    <parent link="left_arm_base_link"/>
    <child link="left_arm_link1"/>
    <origin xyz="0 0 0.15" rpy="0 0 0"/>
    <axis xyz="0 0 1"/>
    <limit lower="-3.14159" upper="3.14159" effort="100" velocity="3.0"/>
  </joint>
  <link name="left_arm_link1"/>

  <joint name="left_arm_joint2" type="revolute">
    <parent link="left_arm_link1"/>
    <child link="left_arm_link2"/>
    <origin xyz="0 0 0.10" rpy="0 0 0"/>
    <axis xyz="0 1 0"/>
    <limit lower="-2.0" upper="2.0" effort="100" velocity="3.0"/>
  </joint>
  <link name="left_arm_link2"/>

  <joint name="left_arm_joint3" type="revolute">
    <parent link="left_arm_link2"/>
    <child link="left_arm_link3"/>
    <origin xyz="0 0 0.35" rpy="0 0 0"/>
    <axis xyz="0 1 0"/>
    <limit lower="-2.6" upper="2.6" effort="100" velocity="3.0"/>
  </joint>
  <link name="left_arm_link3"/>

  <joint name="left_arm_joint4" type="revolute">
    <parent link="left_arm_link3"/>
    <child link="left_arm_link4"/>
    <origin xyz="0 0 0.30" rpy="0 0 0"/>
    <axis xyz="0 0 1"/>
    <limit lower="-3.14159" upper="3.14159" effort="50" velocity="3.5"/>
  </joint>
  <link name="left_arm_link4"/>

  <joint name="left_arm_joint5" type="revolute">
    <parent link="left_arm_link4"/>
    <child link="left_arm_link5"/>
    <origin xyz="0 0 0.05" rpy="0 0 0"/>
    <axis xyz="0 1 0"/>
    <limit lower="-2.0" upper="2.0" effort="50" velocity="3.5"/>
  </joint>
  <link name="left_arm_link5"/>

  <joint name="left_arm_joint6" type="revolute">
    <parent link="left_arm_link5"/>
    <child link="left_arm_link6"/>
    <origin xyz="0 0 0.05" rpy="0 0 0"/>
    <axis xyz="0 0 1"/>
    <limit lower="-3.14159" upper="3.14159" effort="50" velocity="3.5"/>
  </joint>
  <link name="left_arm_link6"/>

  <joint name="left_arm_tool0_fixed" type="fixed">
    <parent link="left_arm_link6"/>
    <child link="left_arm_tool0"/>
    <origin xyz="0 0 0.10" rpy="0 0 0"/>
  </joint>
  <link name="left_arm_tool0"/>

  <!-- ===================== RIGHT ARM ===================== -->
  <joint name="right_arm_mount" type="fixed">
    <parent link="base_link"/>
    <child link="right_arm_base_link"/>
    <origin xyz="0 -0.25 0" rpy="0 0 0"/>
  </joint>
  <link name="right_arm_base_link"/>

  <joint name="right_arm_joint1" type="revolute">
    <parent link="right_arm_base_link"/>
    <child link="right_arm_link1"/>
    <origin xyz="0 0 0.15" rpy="0 0 0"/>
    <axis xyz="0 0 1"/>
    <limit lower="-3.14159" upper="3.14159" effort="100" velocity="3.0"/>
  </joint>
  <link name="right_arm_link1"/>

  <joint name="right_arm_joint2" type="revolute">
    <parent link="right_arm_link1"/>
    <child link="right_arm_link2"/>
    <origin xyz="0 0 0.10" rpy="0 0 0"/>
    <axis xyz="0 1 0"/>
    <limit lower="-2.0" upper="2.0" effort="100" velocity="3.0"/>
  </joint>
  <link name="right_arm_link2"/>

  <joint name="right_arm_joint3" type="revolute">
    <parent link="right_arm_link2"/>
    <child link="right_arm_link3"/>
    <origin xyz="0 0 0.35" rpy="0 0 0"/>
    <axis xyz="0 1 0"/>
    <limit lower="-2.6" upper="2.6" effort="100" velocity="3.0"/>
  </joint>
  <link name="right_arm_link3"/>

  <joint name="right_arm_joint4" type="revolute">
    <parent link="right_arm_link3"/>
    <child link="right_arm_link4"/>
    <origin xyz="0 0 0.30" rpy="0 0 0"/>
    <axis xyz="0 0 1"/>
    <limit lower="-3.14159" upper="3.14159" effort="50" velocity="3.5"/>
  </joint>
  <link name="right_arm_link4"/>

  <joint name="right_arm_joint5" type="revolute">
    <parent link="right_arm_link4"/>
    <child link="right_arm_link5"/>
    <origin xyz="0 0 0.05" rpy="0 0 0"/>
    <axis xyz="0 1 0"/>
    <limit lower="-2.0" upper="2.0" effort="50" velocity="3.5"/>
  </joint>
  <link name="right_arm_link5"/>

  <joint name="right_arm_joint6" type="revolute">
    <parent link="right_arm_link5"/>
    <child link="right_arm_link6"/>
    <origin xyz="0 0 0.05" rpy="0 0 0"/>
    <axis xyz="0 0 1"/>
    <limit lower="-3.14159" upper="3.14159" effort="50" velocity="3.5"/>
  </joint>
  <link name="right_arm_link6"/>

  <joint name="right_arm_tool0_fixed" type="fixed">
    <parent link="right_arm_link6"/>
    <child link="right_arm_tool0"/>
    <origin xyz="0 0 0.10" rpy="0 0 0"/>
  </joint>
  <link name="right_arm_tool0"/>
</robot>
